Нет соединения с сервером сайта: https://instagram.com
Traceback (most recent call last):
  File "C:\pythonProject\urban-university\Super_New_venv\lib\site-packages\urllib3\connection.py", line 198, in _new_conn
    sock = connection.create_connection(
  File "C:\pythonProject\urban-university\Super_New_venv\lib\site-packages\urllib3\util\connection.py", line 60, in create_connection
    for res in socket.getaddrinfo(host, port, family, socket.SOCK_STREAM):
  File "C:\Python310\lib\socket.py", line 955, in getaddrinfo
    for res in _socket.getaddrinfo(host, port, family, type, proto, flags):
socket.gaierror: [Errno 11001] getaddrinfo failed

The above exception was the direct cause of the following exception:

Traceback (most recent call last):
  File "C:\pythonProject\urban-university\Super_New_venv\lib\site-packages\urllib3\connectionpool.py", line 793, in urlopen
    response = self._make_request(
  File "C:\pythonProject\urban-university\Super_New_venv\lib\site-packages\urllib3\connectionpool.py", line 491, in _make_request
    raise new_e
  File "C:\pythonProject\urban-university\Super_New_venv\lib\site-packages\urllib3\connectionpool.py", line 467, in _make_request
    self._validate_conn(conn)
  File "C:\pythonProject\urban-university\Super_New_venv\lib\site-packages\urllib3\connectionpool.py", line 1099, in _validate_conn
    conn.connect()
  File "C:\pythonProject\urban-university\Super_New_venv\lib\site-packages\urllib3\connection.py", line 616, in connect
    self.sock = sock = self._new_conn()
  File "C:\pythonProject\urban-university\Super_New_venv\lib\site-packages\urllib3\connection.py", line 205, in _new_conn
    raise NameResolutionError(self.host, self, e) from e
urllib3.exceptions.NameResolutionError: <urllib3.connection.HTTPSConnection object at 0x00000161D4EFFA60>: Failed to resolve 'instagram.com' ([Errno 11001] getaddrinfo failed)

The above exception was the direct cause of the following exception:

Traceback (most recent call last):
  File "C:\pythonProject\urban-university\Super_New_venv\lib\site-packages\requests\adapters.py", line 486, in send
    resp = conn.urlopen(
  File "C:\pythonProject\urban-university\Super_New_venv\lib\site-packages\urllib3\connectionpool.py", line 847, in urlopen
    retries = retries.increment(
  File "C:\pythonProject\urban-university\Super_New_venv\lib\site-packages\urllib3\util\retry.py", line 515, in increment
    raise MaxRetryError(_pool, url, reason) from reason  # type: ignore[arg-type]
urllib3.exceptions.MaxRetryError: HTTPSConnectionPool(host='instagram.com', port=443): Max retries exceeded with url: / (Caused by NameResolutionError("<urllib3.connection.HTTPSConnection object at 0x00000161D4EFFA60>: Failed to resolve 'instagram.com' ([Errno 11001] getaddrinfo failed)"))

During handling of the above exception, another exception occurred:

Traceback (most recent call last):
  File "C:\pythonProject\urban-university\12_Development_cycle_support\20240115_Logging\main_threading.py", line 41, in run
    response = requests.get(self.site, timeout=3)
  File "C:\pythonProject\urban-university\Super_New_venv\lib\site-packages\requests\api.py", line 73, in get
    return request("get", url, params=params, **kwargs)
  File "C:\pythonProject\urban-university\Super_New_venv\lib\site-packages\requests\api.py", line 59, in request
    return session.request(method=method, url=url, **kwargs)
  File "C:\pythonProject\urban-university\Super_New_venv\lib\site-packages\requests\sessions.py", line 589, in request
    resp = self.send(prep, **send_kwargs)
  File "C:\pythonProject\urban-university\Super_New_venv\lib\site-packages\requests\sessions.py", line 703, in send
    r = adapter.send(request, **kwargs)
  File "C:\pythonProject\urban-university\Super_New_venv\lib\site-packages\requests\adapters.py", line 519, in send
    raise ConnectionError(e, request=request)
requests.exceptions.ConnectionError: HTTPSConnectionPool(host='instagram.com', port=443): Max retries exceeded with url: / (Caused by NameResolutionError("<urllib3.connection.HTTPSConnection object at 0x00000161D4EFFA60>: Failed to resolve 'instagram.com' ([Errno 11001] getaddrinfo failed)"))
Сервер болеет, можно попробовать ретрай через N секунд: https://twitter.com
Traceback (most recent call last):
  File "C:\pythonProject\urban-university\Super_New_venv\lib\site-packages\urllib3\connectionpool.py", line 467, in _make_request
    self._validate_conn(conn)
  File "C:\pythonProject\urban-university\Super_New_venv\lib\site-packages\urllib3\connectionpool.py", line 1099, in _validate_conn
    conn.connect()
  File "C:\pythonProject\urban-university\Super_New_venv\lib\site-packages\urllib3\connection.py", line 653, in connect
    sock_and_verified = _ssl_wrap_socket_and_match_hostname(
  File "C:\pythonProject\urban-university\Super_New_venv\lib\site-packages\urllib3\connection.py", line 806, in _ssl_wrap_socket_and_match_hostname
    ssl_sock = ssl_wrap_socket(
  File "C:\pythonProject\urban-university\Super_New_venv\lib\site-packages\urllib3\util\ssl_.py", line 465, in ssl_wrap_socket
    ssl_sock = _ssl_wrap_socket_impl(sock, context, tls_in_tls, server_hostname)
  File "C:\pythonProject\urban-university\Super_New_venv\lib\site-packages\urllib3\util\ssl_.py", line 509, in _ssl_wrap_socket_impl
    return ssl_context.wrap_socket(sock, server_hostname=server_hostname)
  File "C:\Python310\lib\ssl.py", line 512, in wrap_socket
    return self.sslsocket_class._create(
  File "C:\Python310\lib\ssl.py", line 1070, in _create
    self.do_handshake()
  File "C:\Python310\lib\ssl.py", line 1341, in do_handshake
    self._sslobj.do_handshake()
TimeoutError: _ssl.c:980: The handshake operation timed out

The above exception was the direct cause of the following exception:

Traceback (most recent call last):
  File "C:\pythonProject\urban-university\Super_New_venv\lib\site-packages\requests\adapters.py", line 486, in send
    resp = conn.urlopen(
  File "C:\pythonProject\urban-university\Super_New_venv\lib\site-packages\urllib3\connectionpool.py", line 847, in urlopen
    retries = retries.increment(
  File "C:\pythonProject\urban-university\Super_New_venv\lib\site-packages\urllib3\util\retry.py", line 470, in increment
    raise reraise(type(error), error, _stacktrace)
  File "C:\pythonProject\urban-university\Super_New_venv\lib\site-packages\urllib3\util\util.py", line 39, in reraise
    raise value
  File "C:\pythonProject\urban-university\Super_New_venv\lib\site-packages\urllib3\connectionpool.py", line 793, in urlopen
    response = self._make_request(
  File "C:\pythonProject\urban-university\Super_New_venv\lib\site-packages\urllib3\connectionpool.py", line 491, in _make_request
    raise new_e
  File "C:\pythonProject\urban-university\Super_New_venv\lib\site-packages\urllib3\connectionpool.py", line 469, in _make_request
    self._raise_timeout(err=e, url=url, timeout_value=conn.timeout)
  File "C:\pythonProject\urban-university\Super_New_venv\lib\site-packages\urllib3\connectionpool.py", line 370, in _raise_timeout
    raise ReadTimeoutError(
urllib3.exceptions.ReadTimeoutError: HTTPSConnectionPool(host='twitter.com', port=443): Read timed out. (read timeout=3)

During handling of the above exception, another exception occurred:

Traceback (most recent call last):
  File "C:\pythonProject\urban-university\12_Development_cycle_support\20240115_Logging\main_threading.py", line 41, in run
    response = requests.get(self.site, timeout=3)
  File "C:\pythonProject\urban-university\Super_New_venv\lib\site-packages\requests\api.py", line 73, in get
    return request("get", url, params=params, **kwargs)
  File "C:\pythonProject\urban-university\Super_New_venv\lib\site-packages\requests\api.py", line 59, in request
    return session.request(method=method, url=url, **kwargs)
  File "C:\pythonProject\urban-university\Super_New_venv\lib\site-packages\requests\sessions.py", line 589, in request
    resp = self.send(prep, **send_kwargs)
  File "C:\pythonProject\urban-university\Super_New_venv\lib\site-packages\requests\sessions.py", line 703, in send
    r = adapter.send(request, **kwargs)
  File "C:\pythonProject\urban-university\Super_New_venv\lib\site-packages\requests\adapters.py", line 532, in send
    raise ReadTimeout(e, request=request)
requests.exceptions.ReadTimeout: HTTPSConnectionPool(host='twitter.com', port=443): Read timed out. (read timeout=3)
